try {
  const { p1, p2 } = func(arg);
  doSomething(p1, p2);
} catch (err) {
  handleError(err);
}
